Workbook

Sheet 1-1_体裁の対比
B2: 1-1. 体裁を統一できる ― 良い例と悪い例の対比
D5: 【良い例】体裁が統一されている
D7: 施設 | E7: 客室数(室) | F7: 稼働日数/月 | G7: 稼働率 | H7: ADR(円) | I7: 売上(千円)
D8: 西伊豆 | E8: 30 | F8: 30 | G8: 0.68 | H8: 52000 | I8: =E8*F8*G8*H8/10^3
D9: 熱海 | E9: 30 | F9: 30 | G9: 0.72 | H9: 61000 | I9: =E9*F9*G9*H9/10^3
D10: 箱根 | E10: 3 | F10: 30 | G10: 0.65 | H10: 150000 | I10: =E10*F10*G10*H10/10^3
D11: 合計 | E11: =SUM(E8:E10) | I11: =SUM(I8:I10)
D13: ★ 罫線や色、太字は必要最小限に。 意図なく色を使わない
D14: ★ %は0.0%で桁統一／金額は#,##0
D15: ★ セル結合しない
D16: ★ 十分に行で余白を取る
D20: 【悪い例】体裁が崩れている（★が崩れポイント）
D21: 施設 | E21: 客室数 | F21: 稼働日数 | G21: 稼働 | H21: ADR | I21: 売上
D22: 西伊豆 | E22: 30 | F22: 30 | G22: 0.68 | H22: 52000円 | I22: =E22*F22*G22*H22/10^3
D23: 熱海 | E23: 30 | F23: 30 | G23: 0.72 | H23: 61000 | I23: =E23*F23*G23*H23/10^3
D24: 箱根 | E24: 3 | F24: 30 | G24: 0.65 | H24: 150000 | I24: =E24*F24*G24*H24/10^3
D25: 合計 | I25: =SUM(I22:I24)
D26: ★ 罫線や色使いに無駄が多く、作業時間を浪費。 視線が誘導されない。
D27: ★ 色を役割でなく気分で多用
D28: ★ ADR・売上に「円/千円」単位が混在し、52000円は文字列で計算不可
D29: ★ 小数点以下が無意味に多い（0.00000、#,##0.00）
D30: ★ セル結合している
D31: ★ 十分に行で余白を取れいていない

Sheet 1-2_操作イメージ
B2: 1-2. 操作が速い ― キーボード操作と数式展開のイメージ
D5: ① キーボードでセル間・表間を高速移動する
D7: 操作イメージ | E7: キー | G7: 効果
D8: 表の端まで一気に移動 | E8: Ctrl + 方向キー | G8: データの切れ目まで一瞬でジャンプ
D9: 端まで一括で範囲選択 | E9: Ctrl + Shift + 方向キー | G9: そこから端までを選択（合計や書式設定に）
D10: シートを切り替える | E10: Ctrl + PgDn / PgUp | G10: 右/左のシートへ移動
D11: セルを編集モードに | E11: F2 | G11: マウスなしで数式を編集、もう一度押すとセル選択モード
D13: ※ 下の水色の範囲は「Ctrl+Shift+↓, → で一括選択される範囲」のイメージです。
D14: 月 | E14: 売上(円)
D15: 7月 | E15: 7072000
D16: 8月 | E16: 8130000
D17: 9月 | E17: 6540000
D18: 10月 | E18: 5980000
D19: 合計 | E19: =SUM(E15:E18)
D23: ② 数式を縦・横に正しく展開する（相対参照）
D25: G列は =D×E を1つ作って下へコピー（青色セル）するだけ。参照が自動でずれる（相対参照）。
D26: 商品 | E26: 単価(円) | F26: 数量 | G26: 金額(円)
D27: シングル | E27: 12000 | F27: 30 | G27: =E27*F27
D28: ツイン | E28: 18000 | F28: 22 | G28: =E28*F28
D29: スイート | E29: 52000 | F29: 8 | G29: =E29*F29
D31: 作業手順
D32: G27で、 Ctrl+C（コピー） ➡ Ctrl+Shift+↓（範囲選択） ➡ alt, E, S, F（数式貼り付け）
D35: ③ 絶対/相対/複合参照を使い分ける（$の位置）
D37: $D ＝列固定、 $38 ＝行固定。 F4キーで $ の位置を切替。
D38: 数量＼単価 | E38: 10000 | F38: 20000 | G38: 30000 | H38: 50000
D39: 1 | E39: =$D39*E$38 | F39: =$D39*F$38 | G39: =$D39*G$38 | H39: =$D39*H$38
D40: 2 | E40: =$D40*E$38 | F40: =$D40*F$38 | G40: =$D40*G$38 | H40: =$D40*H$38
D41: 3 | E41: =$D41*E$38 | F41: =$D41*F$38 | G41: =$D41*G$38 | H41: =$D41*H$38
D42: 5 | E42: =$D42*E$38 | F42: =$D42*F$38 | G42: =$D42*G$38 | H42: =$D42*H$38
D43: 10 | E43: =$D43*E$38 | F43: =$D43*F$38 | G43: =$D43*G$38 | H43: =$D43*H$38
D45: 作業手順
D46: E39で、F2（セル編集） ➡ F4（$の位置切替） ➡ Enter（編集終了）
D47: E39で、 Ctrl+C（コピー） ➡ Ctrl+Shift+↓, ➞（範囲選択） ➡ alt, E, S, F（数式貼り付け）

Sheet 2-1_実績集計_SUMIFS
B2: 2-1. 実績集計 ― 元データと集計結果（SUMIFS）
D5: ① 元データ：予約明細
D7: 予約ID | E7: 施設 | F7: 月 | G7: 客室タイプ | H7: 泊数 | I7: 宿泊人数 | J7: 売上(円)
D8: R001 | E8: 西伊豆 | F8: 7 | G8: スイート | H8: 2 | I8: 4 | J8: 160000
D9: R002 | E9: 西伊豆 | F9: 7 | G9: スタンダード | H9: 3 | I9: 4 | J9: 108000
D10: R003 | E10: 熱海 | F10: 7 | G10: スタンダード | H10: 2 | I10: 3 | J10: 72000
D11: R004 | E11: 西伊豆 | F11: 8 | G11: スイート | H11: 2 | I11: 2 | J11: 180000
D12: R005 | E12: 熱海 | F12: 8 | G12: スイート | H12: 1 | I12: 2 | J12: 95000
D13: R006 | E13: 西伊豆 | F13: 7 | G13: スタンダード | H13: 1 | I13: 2 | J13: 36000
D14: R007 | E14: 熱海 | F14: 8 | G14: スタンダード | H14: 4 | I14: 6 | J14: 152000
D15: R008 | E15: 西伊豆 | F15: 8 | G15: スタンダード | H15: 2 | I15: 3 | J15: 74000
D16: R009 | E16: 熱海 | F16: 7 | G16: スイート | H16: 1 | I16: 2 | J16: 92000
D17: R010 | E17: 西伊豆 | F17: 8 | G17: スイート | H17: 3 | I17: 5 | J17: 270000
D21: ② 集計：施設別×月別の売上（=SUMIFS）
D23: 施設＼月 | E23: 7 | F23: 8 | G23: 合計
D24: 西伊豆 | E24: =SUMIFS($J$8:$J$17,$E$8:$E$17,$D24,$F$8:$F$17,E$23) | F24: =SUMIFS($J$8:$J$17,$E$8:$E$17,$D24,$F$8:$F$17,F$23) | G24: =SUM(E24:F24)
D25: 熱海 | E25: =SUMIFS($J$8:$J$17,$E$8:$E$17,$D25,$F$8:$F$17,E$23) | F25: =SUMIFS($J$8:$J$17,$E$8:$E$17,$D25,$F$8:$F$17,F$23) | G25: =SUM(E25:F25)
D26: 合計 | E26: =SUM(E24:E25) | F26: =SUM(F24:F25) | G26: =SUM(G24:G25)
D27: 例）D20 = =SUMIFS(売上, 施設, 西伊豆, 月, 7) 。元データを1行足すだけで自動更新。
D32: ③ 集計：客室タイプ別ADR（売上計÷泊数計）
D34: 客室タイプ | E34: 売上計(円) | F34: 泊数計(泊) | G34: ADR(円)
D35: スイート | E35: =SUMIFS($J$8:$J$17,$G$8:$G$17,D35) | F35: =SUMIFS($H$8:$H$17,$G$8:$G$17,D35) | G35: =E35/F35
D36: スタンダード | E36: =SUMIFS($J$8:$J$17,$G$8:$G$17,D36) | F36: =SUMIFS($H$8:$H$17,$G$8:$G$17,D36) | G36: =E36/F36
D38: ADR＝客室売上÷販売室数(泊数)。SUMIFSで分子・分母を集計して割るだけ。

Sheet 2-1_実績集計_XLOOKUP
B2: 2-1. 実績集計 ― 元データと集計結果（XLOOKUP）
D5: ① 元データ：予約明細
D7: 行 | E7: B 商品コード | F7: D 数量 | G7: F 売上(円)
D8: 2 | E8: F-102 | F8: 4 | G8: 32000
D9: 3 | E9: F-101 | F9: 6 | G9: 27000
D10: 4 | E10: F-103 | F10: 5 | G10: 19000
D11: 5 | E11: F-999 | F11: 2 | G11: 12000
D15: ② 元データ：マスター
D17: A 商品コード | E17: B 商品名 | F17: C 原価(円)
D18: F-101 | E18: 金目鯛煮付 | F18: 1800
D19: F-102 | E19: 鮑ステーキ | F19: 3200
D20: F-103 | E20: 地魚刺身盛 | F20: 1500
D25: ③ 集計：商品別売上と原価率
D27: 行 | E27: B 商品コード | F27: C 商品名 | G27: D 数量 | H27: E 原価単価(円) | I27: F 原価計(円) | J27: 売上 | K27: 原価率
D28: 2 | E28: F-102 | F28: =_xlfn.XLOOKUP($E28,$D$17:$D$20,E$17:E$20,"該当なし") | G28: =SUMIFS($F$8:$F$11,$E$8:$E$11,E28) | H28: =_xlfn.XLOOKUP($E28,$D$17:$D$20,F$17:F$20,"該当なし") | I28: =IFERROR(G28*H28,"-") | J28: =SUMIFS($G$8:$G$11,$E$8:$E$11,E28) | K28: =IFERROR(I28/J28,"-")
D29: 3 | E29: F-101 | F29: =_xlfn.XLOOKUP($E29,$D$17:$D$20,E$17:E$20,"該当なし") | G29: =SUMIFS($F$8:$F$11,$E$8:$E$11,E29) | H29: =_xlfn.XLOOKUP($E29,$D$17:$D$20,F$17:F$20,"該当なし") | I29: =IFERROR(G29*H29,"-") | J29: =SUMIFS($G$8:$G$11,$E$8:$E$11,E29) | K29: =IFERROR(I29/J29,"-")
D30: 4 | E30: F-103 | F30: =_xlfn.XLOOKUP($E30,$D$17:$D$20,E$17:E$20,"該当なし") | G30: =SUMIFS($F$8:$F$11,$E$8:$E$11,E30) | H30: =_xlfn.XLOOKUP($E30,$D$17:$D$20,F$17:F$20,"該当なし") | I30: =IFERROR(G30*H30,"-") | J30: =SUMIFS($G$8:$G$11,$E$8:$E$11,E30) | K30: =IFERROR(I30/J30,"-")
D31: 5 | E31: F-999 | F31: =_xlfn.XLOOKUP($E31,$D$17:$D$20,E$17:E$20,"該当なし") | G31: =SUMIFS($F$8:$F$11,$E$8:$E$11,E31) | H31: =_xlfn.XLOOKUP($E31,$D$17:$D$20,F$17:F$20,"該当なし") | I31: =IFERROR(G31*H31,"-") | J31: =SUMIFS($G$8:$G$11,$E$8:$E$11,E31) | K31: =IFERROR(I31/J31,"-")

Sheet 2-2_クリーニング_スピル関数
B2: 2-2. データ加工・クリーニング ― UNIQUE / FILTER / SORT
D4: 元データの予約経路(OTA)には重複があります。動的配列関数でユニークな一覧を作ります。※Excelで開くと自動計算・spillします。
D5: ① 元データ：予約経路つき明細 | I5: ② OTAのユニーク一覧
D7: 予約ID | E7: 予約経路(OTA) | F7: 海外/国内 | G7: 売上(円) | I7: 数式
D8: R001 | E8: 楽天トラベル | F8: 国内 | G8: 160000 | I8: =SORT(UNIQUE(FILTER(#:#,#:#=***)))
D9: R002 | E9: じゃらん | F9: 国内 | G9: 108000 | I9: ↑ このセルに1つ入れるだけで、
D10: R003 | E10: Booking.com | F10: 海外 | G10: 72000 | I10: 重複を除いた経路名が下方向にスピル表示されます。
D11: R004 | E11: 楽天トラベル | F11: 国内 | G11: 180000
D12: R005 | E12: 公式サイト | F12: 国内 | G12: 95000
D13: R006 | E13: じゃらん | F13: 国内 | G13: 36000
D14: R007 | E14: Expedia | F14: 海外 | G14: 152000 | I14: ③ 実例：OTA別の売上集計と FILTER 抽出
D15: R008 | E15: Booking.com | F15: 海外 | G15: 74000
D16: R009 | E16: 楽天トラベル | F16: 国内 | G16: 92000 | I16: OTA | J16: 売上計(円)
D17: R010 | E17: 公式サイト | F17: 国内 | G17: 270000 | I17: {=_xlfn._xlws.SORT(_xlfn.UNIQUE(_xlfn._xlws.FILTER(E8:E19, F8:F19="国内")))} | J17: {=SUMIFS($G$8:$G$19,$E$8:$E$19,_xlfn.ANCHORARRAY(I17))}
D18: R011 | E18: 一休.com | F18: 国内 | G18: 210000 | I18: 一休.com | J18: 210000
D19: R012 | E19: じゃらん | F19: 国内 | G19: 64000 | I19: 楽天トラベル | J19: 432000
E20: ・・・・ | I20: 公式サイト | J20: 365000

Sheet 2-2-2_スピル関数
B2: 2-2-2. データ加工・クリーニング ― スピル関数系（UNIQUE / FILTER / SORTBY / TOCOL / TOROW / DROP / TEXTSPLIT / SEQUENCE）
B3: 各「数式」セル（青）はExcelで開くと自動計算し、下方向・右方向にスピル（spill）します。※動的配列に対応した Microsoft 365 が必要です。
B4: ⚠ 開いたとき数式の先頭に「@」が付く場合があります（例：=@UNIQUE(…)）。その時は数式バーで式の中の「@」をすべて削除し、Enter で確定し直すと正しくスピルします。
B6: 【元データ】予約明細（空白セルと『合計』行をわざと含む） | H6: ① UNIQUE + TOCOL ｜ 空白を集計しない
B7: 予約ID | C7: 予約経路ID | D7: 予約経路 | E7: 区分 | F7: 売上 | H7: UNIQUE で重複除去。 | J7: TOCOL(範囲,1) で1列に畳みつつ空白を無視 → UNIQUE で重複除去。
B8: R001 | C8: RC001 | D8: 楽天トラベル | E8: 国内 | F8: 160000 | H8: =_xlfn.UNIQUE(D:D) | J8: =_xlfn.UNIQUE(_xlfn.TOCOL(D:D,1))
B9: R002 | C9: RC002 | D9: じゃらん | E9: 国内 | F9: 108000
B10: R003 | C10: RC005 | D10: Booking.com | E10: 海外 | F10: 72000
B11: R004 | E11: 国内 | F11: 180000
B12: R005 | C12: RC010 | D12: 公式サイト | E12: 国内 | F12: 95000
B13: R006 | C13: RC002 | D13: じゃらん | E13: 国内 | F13: 36000
B14: R007 | C14: RC008 | D14: Expedia | E14: 海外 | F14: 152000
B15: R008 | E15: 海外 | F15: 74000
B16: R009 | C16: RC001 | D16: 楽天トラベル | E16: 国内 | F16: 92000
B18: ※ C7がヘッダー、C11・C15 が空白 | H18: ② UNIQUE + TOCOL + FILTER ｜ 空白＋特定セル(合計)を除外＝実データのみ
B19: これらを除いて“実データのみ”を取り出すのが右の例です。 | H19: FILTER で『予約経路』を除外 → TOCOL(,1) で空白無視 → UNIQUE。
H20: =_xlfn.UNIQUE(_xlfn.TOCOL(_xlfn._xlws.FILTER(D:D,D:D<>"予約経路"),1))
H30: ③ UNIQUE + TOCOL + DROP ｜ 空白＋先頭の任意行を除外
H31: DROP(範囲,7) で先頭7行を落とす → TOCOL(,1) → UNIQUE。ヘッダや前置き行を飛ばす用途。
H32: =_xlfn.UNIQUE(_xlfn.TOCOL(_xlfn.DROP(D:D,7),1))
H42: ④ ③ + SORT ｜ さらに任意の順で並べ替え（ここでは降順）
H43: SORT(結果, 並べ替えキーの列番号, -1)。キー配列を差し替えれば任意の順に。
H44: =_xlfn._xlws.SORT(_xlfn.UNIQUE(_xlfn.TOCOL(_xlfn.DROP(D:D,7),1)),1,-1)
H54: ⑤ ③ + SORTBY ｜ さらに任意の順で並べ替え（ここでは昇順）
H55: SORTBY(結果, 並べ替えキー, -1)。キー配列を差し替えれば任意の順に。
H56: =_xlfn.SORTBY(_xlfn.UNIQUE(_xlfn.TOCOL(_xlfn.DROP(C:C,7),1)),_xlfn.UNIQUE(_xlfn.TOCOL(_xlfn.DROP(C:C,7),1)),1) | I56: =_xlfn.XLOOKUP(_xlfn.ANCHORARRAY(H56),C:C,D:D)
H66: ⑥ TOCOL / TOROW ｜ データの縦横を変換
H67: TOCOL＝横→縦、TOROW＝縦→横。貼り付け方向を直したい時に。
H68: 横入力→ | I68: 月 | J68: 火 | K68: 水 | L68: 木 | M68: 金
H69: ↓ TOCOL で縦1列に | J69: → TOROW で C8:C10 を横1行に
H70: =_xlfn.TOCOL(I68:M68) | J70: =_xlfn.TOROW(D8:D10)
H80: ⑦ TOCOL + TEXTSPLIT ｜ カンマ区切り文字列を縦1列に
H81: web/PDFの表を貼れない時、カンマ区切りテキストを縦のリストに展開できる。
H82: 入力→ | I82: りんご,みかん,ぶどう,いちご,かき
H84: =_xlfn.TOCOL(_xlfn.TEXTSPLIT(I82,","))
H94: ⑧ SEQUENCE + ROWS ｜ データ件数ぶんの連番を自動生成
H95: ROWS で件数を数え、その数だけ連番を作る。行が増減しても自動追従。
H96: =_xlfn.SEQUENCE(ROWS(_xlfn.ANCHORARRAY(H44))) | I96: =_xlfn.ANCHORARRAY(H44)
H102: ⑨ EOMONTH + SEQUENCE ｜ 5年分の“月初(X月1日)”を横にスピル
H103: SEQUENCE(1,60,0) で 0〜59 か月を作り、EOMONTH(基準,n)+1 で各月の1日に。基準日を変えると全体が動く。
...

Sheet 2-3_演算子
B2: 2-3. 演算子を使いこなす ― 問題集（& / # / .: :. / * ? ~ / " ' ^）
B3: 右の『解答欄』に自分で式を入れ、いちばん右の『解答例』で答え合わせをしてください。
B5: ▼ 演算子の早見
B6: & | D6: 文字・式の連結。条件式は ">="&B2 のように作る
B7: # | D7: スピル範囲演算子。左上セル＋# で こぼれ範囲全体
B8: .: / :. / .:. | D8: トリム参照。先頭/末尾/両側の空白行・列を切り詰め
B9: * ? ~ | D9: ワイルドカード。任意文字列/1文字/エスケープ
B10: " ' ^ | D10: 文字列リテラル/文字列化・0落ち防止/べき乗
B13: ▼ 問題
B14: No. | C14: ねらい | D14: 問題 | G14: 解答欄 | I14: 解答例
B15: Q1 | C15: & | D15: 基準値がセルB2にある。C列売上のうち「B2以上」の合計をSUMIFで求める | I15: =SUMIF(C:C,">="&B2)
B16: Q2 | C16: & | D16: 姓A2と名B2を、間に半角スペースを入れて連結する | I16: =A2&" "&B2
B17: Q3 | C17: & | D17: D列の点数で「E1以上 E2未満」の件数をCOUNTIFSで数える | I17: =COUNTIFS(D:D,">="&E1,D:D,"<"&E2)
B18: Q4 | C18: # | D18: G2に =UNIQUE(A2:A1000) の結果。その件数を数える | I18: =COUNTA(G2#)
B19: Q5 | C19: トリム | D19: A列(末尾に空白)の合計を、最後のデータまでで求める | I19: =SUM(A2:.A)
B20: Q6 | C20: * ? | D20: A列に「ホテル」を含む行の、C列売上を合計する | I20: =SUMIF(A:A,"*ホテル*",C:C)
B21: Q7 | C21: ~ | D21: A列で、文字どおり「?」で終わるセルの数を数える | I21: =COUNTIF(A:A,"*~?")
B22: Q8 | C22: ^ | D22: セルB2の値の平方根を、べき乗演算子で求める | I22: =B2^0.5
B23: Q9 | C23: " | D23: A1の中身を前後ダブルクオートで囲んだ文字列で表示する | I23: =""""&A1&""""

Sheet 2-5_PL①Input
B2: 2-5. PLシミュレーション ①Input（前提・青字が入力）
D4: 青字のセルだけを変更すれば、②計算・③Outputが自動で更新されます。
D5: 【売上ドライバー】
D7: 項目 | E7: 値 | F7: 単位
D8: 客室数 | E8: 20 | F8: 室
D9: 営業日数 | E9: 365 | F9: 日
D10: 稼働率 | E10: 0.65
D11: ADR（客室単価） | E11: 50000 | F11: 円
D12: 宿泊人数/室 | E12: 2 | F12: 人
D13: 飲食単価/人 | E13: 6000 | F13: 円
D17: 【コストドライバー】
D19: 項目 | E19: 値 | F19: 単位
D20: 変動費率（対売上） | E20: 0.3
D21: 人件費（固定・年） | E21: 60000000 | F21: 円
D22: その他固定費（年） | E22: 48000000 | F22: 円
D24: ※ 青字＝手入力の前提。黒字＝数式。緑字＝他シート参照（②③で使用）。

Sheet 2-5_PL②計算
B2: 2-5. PLシミュレーション ②計算（Inputを参照して積み上げ）
D4: 重要！：原則、青字、緑字、黒字を1セルにごっちゃにして計算しない。
D5: 客室・飲食売上の積み上げ
D7: 項目 | E7: 金額(円) | F7: 計算の内容
D8: 客室数 | E8: ='2-5_PL①Input'!E8 | F8: Inputシートより
D9: 営業日数 | E9: ='2-5_PL①Input'!E9 | F9: Inputシートより
D10: 稼働率 | E10: ='2-5_PL①Input'!E10 | F10: Inputシートより
D11: 稼働室数（室・年） | E11: =E8*E9*E10 | F11: 客室数×営業日数×稼働率
D13: ='2-5_PL①Input'!$D$11 | E13: ='2-5_PL①Input'!E11 | F13: Inputシートより
D14: 客室売上 | E14: =E11*E13 | F14: 販売室数×ADR
D16: 宿泊人数/室 | E16: ='2-5_PL①Input'!E12 | F16: Inputシートより
D17: ='2-5_PL①Input'!$D$13 | E17: ='2-5_PL①Input'!E13 | F17: Inputシートより
D18: 飲食売上 | E18: =E11*E16*E17 | F18: 稼働室数x宿泊人数/室×飲食単価/人
D20: 売上高 計 | E20: =E14+E18 | F20: 客室売上＋飲食売上
D22: 変動費率 | E22: ='2-5_PL①Input'!E20 | F22: Inputシートより
D23: 変動費 | E23: =E20*E22 | F23: 売上高×変動費率
D24: 限界利益 | E24: =E20-E23 | F24: 売上高−変動費
D26: ='2-5_PL①Input'!D21 | E26: ='2-5_PL①Input'!E21
D27: ='2-5_PL①Input'!D22 | E27: ='2-5_PL①Input'!E22
D28: 固定費 計 | E28: =SUM(E26:E27) | F28: 人件費＋その他固定費
D30: 営業利益 | E30: =E24-E28 | F30: 限界利益−固定費
D32: 緑字＝①Inputへの参照。黄色＝主要な中間・最終アウトプット。

Sheet 2-5_PL③Output
B2: 2-5. PLシミュレーション ③Output（PLサマリ）
D4: PPTに張り付けるサマリなどは、数字の色を付けません。
D5: 年間 損益計算書（サマリ）
D6: 単位： 百万円
D8: 項目 | E8: 金額 | F8: 対売上%
D9: 売上高 | E9: ='2-5_PL②計算'!E20/10^6 | F9: =E9/$E$9
D11: 変動費 | E11: ='2-5_PL②計算'!E23/10^6 | F11: =-E11/$E$9
D12: 限界利益 | E12: =E9-E11 | F12: =E12/$E$9
D14: 固定費 | E14: ='2-5_PL②計算'!E28/10^6 | F14: =-E14/$E$9
D15: 営業利益 | E15: =E12-E14 | F15: =E15/$E$9
D17: Input①の青字（稼働率・ADR等）を変えると、この③まで一気に更新されます。

Sheet 00_Index
B2: 00_Index ― 目次・ファイル概要
D4: このファイルの目的：施設別の月次売上を、元データから集計してKPIを出力する実績集計ブック（入力→計算→出力→検証を分離）。
D5: 更新日 / 前提の要約
D7: 項目 | E7: 内容 | F7: 更新日
D8: 対象期間 | E8: 2026年7月〜8月 | F8: 2026-07-20
D9: 消費税率 | E9: 10%（税抜集計） | F9: 2026-07-20
D10: 対象施設 | E10: 西伊豆・熱海（Masterシート参照） | F10: 2026-07-20
D14: シート構成
D16: シート | E16: 役割 | F16: 区分
D17: 00_Index | E17: 目次・目的・更新日・前提の要約 | F17: 案内
D18: 01_Assumption | E18: 前提条件・置き値（青字入力を集約） | F18: 入力
D19: 02_RawData | E19: 加工前の元データ（触らない） | F19: 元データ
D20: 03_Master | E20: 施設・OTAなどのマスタ | F20: マスタ
D21: 04_Calculation | E21: 集計・計算ロジック | F21: 計算
D22: 05_Output | E22: 結果表・KPI | F22: 出力
D23: 06_Check | E23: エラーチェック・整合性確認 | F23: 検証

Sheet 01_Assumption
B2: 01_Assumption ― 前提条件（青字が入力）
D5: 前提・置き値
D7: 項目 | E7: 値 | F7: 単位
D8: 消費税率 | E8: 0.1
D9: 集計対象月・開始 | E9: 7 | F9: 月
D10: 集計対象月・終了 | E10: 8 | F10: 月
D11: 目標稼働率 | E11: 0.7

Sheet 02_RawData
B2: 02_RawData ― 元データ（加工しない）
D4: このシートは元データ。数式や加工を入れず、そのまま保持する。
D5: 元データ（予約明細）
D7: 予約ID | E7: 施設 | F7: 月 | G7: 客室タイプ | H7: 泊数 | I7: 売上税抜(円)
D8: R001 | E8: 西伊豆 | F8: 7 | G8: スイート | H8: 2 | I8: 160000
D9: R002 | E9: 西伊豆 | F9: 7 | G9: スタンダード | H9: 3 | I9: 108000
D10: R003 | E10: 熱海 | F10: 7 | G10: スタンダード | H10: 2 | I10: 72000
D11: R004 | E11: 西伊豆 | F11: 8 | G11: スイート | H11: 2 | I11: 180000
D12: R005 | E12: 熱海 | F12: 8 | G12: スイート | H12: 1 | I12: 95000
D13: R006 | E13: 西伊豆 | F13: 7 | G13: スタンダード | H13: 1 | I13: 36000
D14: R007 | E14: 熱海 | F14: 8 | G14: スタンダード | H14: 4 | I14: 152000
D15: R008 | E15: 西伊豆 | F15: 8 | G15: スタンダード | H15: 2 | I15: 74000
D16: R009 | E16: 熱海 | F16: 7 | G16: スイート | H16: 1 | I16: 92000
D17: R010 | E17: 西伊豆 | F17: 8 | G17: スイート | H17: 3 | I17: 270000

Sheet 03_Master
B2: 03_Master ― マスタ
D5: 施設マスタ
D7: 施設 | E7: 客室数(室) | F7: エリア
D8: 西伊豆 | E8: 20 | F8: 静岡
D9: 熱海 | E9: 15 | F9: 静岡

Sheet 04_Calculation
B2: 04_Calculation ― 集計（RawData/Masterを参照）
D5: 施設別 売上集計
D7: 施設 | E7: 売上計(円) | F7: 売上構成% | G7: 客室数(室) | H7: 1室売上(円)
D8: 西伊豆 | E8: =SUMIFS('02_RawData'!$I$8:$I$17,'02_RawData'!$E$8:$E$17,D8) | F8: =E8/$E$10 | G8: =SUMIFS('03_Master'!$E$8:$E$9,'03_Master'!$D$8:$D$9,D8) | H8: =E8/G8
D9: 熱海 | E9: =SUMIFS('02_RawData'!$I$8:$I$17,'02_RawData'!$E$8:$E$17,D9) | F9: =E9/$E$10 | G9: =SUMIFS('03_Master'!$E$8:$E$9,'03_Master'!$D$8:$D$9,D9) | H9: =E9/G9
D10: 合計 | E10: =SUM(E8:E9) | F10: =E10/$E$10 | G10: =SUM(G8:G9)

Sheet 05_Output
B2: 05_Output ― KPI（Calculationを参照）
D5: 主要KPI
D7: KPI | E7: 値
D8: 総売上(円) | E8: ='04_Calculation'!E10
D10: 西伊豆 構成比 | E10: ='04_Calculation'!F8
D11: 熱海 構成比 | E11: ='04_Calculation'!F9

Sheet 06_Check
B2: 06_Check ― 整合性チェック
D4: 判定がすべてOKなら、集計は元データと整合。1つでも要確認なら原因を追う。
D5: チェック項目
D7: チェック項目 | E7: 値A | F7: 値B | H7: 判定
D8: 元データ件数 = 集計対象件数 | E8: =COUNTA('02_RawData'!$D$8:$D$17) | F8: 10 | G8: =F8-E8 | H8: =IF(G8<0.0001,"OK","要確認")
D9: 施設別売上合計 = 総売上 | E9: ='04_Calculation'!E8+'04_Calculation'!E9 | F9: ='04_Calculation'!E10 | G9: =F9-E9 | H9: =IF(G9<0.0001,"OK","要確認")
D10: 構成比合計 = 100% | E10: ='05_Output'!E10+'05_Output'!E11 | F10: 1 | G10: =F10-E10 | H10: =IF(G10<0.0001,"OK","要確認")

Sheet 4-1_チェックセル
B2: 4-1. チェックセルを設ける
D4: 「別ルートで出した2つの値が一致するか」を機械的に判定。1つでも要確認なら全体を疑う。
D5: 一致チェック
D7: チェック項目 | E7: 値A | F7: 値B | G7: 差(A−B) | H7: 判定
D8: 月次合計 = 年次合計 | E8: 84000000 | F8: 84000000 | G8: =E8-F8 | H8: =IF(ABS(G8)<1,"OK","要確認")
D9: 部門別売上合計 = 全社売上 | E9: 84000000 | F9: 84000000 | G9: =E9-F9 | H9: =IF(ABS(G9)<1,"OK","要確認")
D10: 元データ件数 = 集計後件数 | E10: 1200 | F10: 1200 | G10: =E10-F10 | H10: =IF(ABS(G10)<1,"OK","要確認")
D11: 税抜×1.1 = 税込 | E11: 92400000 | F11: 92400000 | G11: =E11-F11 | H11: =IF(ABS(G11)<1,"OK","要確認")
D12: 構成比の合計 = 100% | E12: 1 | F12: 0.99834336 | G12: =E12-F12 | H12: =IF(ABS(G12)<0.0001,"OK","要確認")

Sheet 4-3_常識チェック
B2: 4-3. 常識との整合性を確認する
D4: 数式が正しくても前提が非常識なら結論は誤り。「桁」と「率」を常識レンジと突き合わせる。
D5: 常識レンジとの照合
D7: 指標 | E7: 値 | F7: 常識レンジ | G7: 判定 | H7: コメント
D8: 1日あたり販売室数（客室10室） | E8: 15 | F8: 0〜10室 | G8: =IF(E8<=10,"OK","異常") | H8: 客室数を超えて販売している
D9: 料理原価率 | E9: 0.05 | F9: 20%〜40% | G9: =IF(AND(E9>=0.2,E9<=0.4),"OK","異常") | H9: 5%は低すぎ（仕入計上漏れの疑い）
D10: 正社員1人あたり人件費（月） | E10: 50000 | F10: 25〜40万円/月 | G10: =IF(AND(E10>=250000,E10<=400000),"OK","異常") | H10: 月5万円は非現実的（年額混同の疑い）
D12: すべて意図的に「異常」になる例です。IF＋AND で常識レンジ内かを自動判定できます。
